Workbook

Sheet 00_Resumen
A1: Amelí · Sistema maestro del menú digital multilingüe
A2: Archivo preparado para menú QR mobile-first, traducciones, precios, ingeniería de menú, alérgenos, multimedia, SEO, canales y estadísticas.
A4: Indicador | B4: Resultado | D4: Flujo de trabajo recomendado
A5: Total de productos | B5: =COUNTA(02_Productos_MASTER!A5:A59) -> 55 | D5: 1 | E5: Validar nombres, descripciones y categorías | F5: 01_Menú_Multilingüe
A6: Productos activos | B6: =COUNTIF(02_Productos_MASTER!J5:J59,"Sí") -> 55 | D6: 2 | E6: Completar precios y costos | F6: 04_Precios
A7: Categorías | B7: =COUNTA(03_Categorías!A5:A17) -> 13 | D7: 3 | E7: Validar ingredientes y alérgenos | F7: 06_Ingredientes / 07_Alérgenos_Dietas
A8: Traducciones completas | B8: =COUNTIF(01_Menú_Multilingüe!N5:N59,"Completa") -> 55 | D8: 4 | E8: Cargar fotografías, enlaces y URL base | F8: 10_Multimedia_SEO / 13_Configuración
A9: Precios cargados | B9: =COUNT(04_Precios!D5:D59) -> 0 | D9: 5 | E9: Definir visibilidad y temporalidad | F9: 11_Canales_QR
A10: Fotografías cargadas | B10: =COUNTIF(10_Multimedia_SEO!C5:C59,"<>") -> 0 | D10: 6 | E10: Cargar ventas y medir interacción | F10: 12_Estadísticas
A11: Unidades vendidas registradas | B11: =SUM(12_Estadísticas!C5:C59) -> 0 | D11: 7 | E11: Tomar decisiones de ingeniería de menú | F11: 09_Ingeniería_Menú
A12: Productos clasificados | B12: =COUNTIF(09_Ingeniería_Menú!L5:L59,"Estrella")+COUNTIF(09_Ingeniería_Menú!L5:L59,"Caballo de batalla")+COUNTIF(09_Ingeniería_Menú!L5:L59,"Incógnita")+COUNTIF(09_Ingeniería_Menú!L5:L59,"Perro") -> 0
A15: Orden | B15: Categoría | C15: Productos | E15: Notas críticas antes de publicar
A16: 1 | B16: Desayunos & Meriendas | C16: =03_Categorías!M5 -> 4 | E16: • | F16: No tratar «Sin TACC» como garantía sin validar certificación y manipulación.
A17: 2 | B17: Delicias | C17: =03_Categorías!M6 -> 7 | E17: • | F17: No publicar alérgenos basados únicamente en el nombre del producto.
A18: 3 | B18: Té en Hebras | C18: =03_Categorías!M7 -> 1 | E18: • | F18: Mantener el QR físico permanente; controlar promociones y disponibilidad desde la web.
A19: 4 | B19: Tisanas | C19: =03_Categorías!M8 -> 3 | E19: • | F19: Las etiquetas «Más vendido» y la clasificación deben provenir de datos reales.
A20: 5 | B20: Blends | C20: =03_Categorías!M9 -> 4 | E20: • | F20: Revisar precios, disponibilidad y horarios antes de cada temporada turística.
A21: 6 | B21: Especiales | C21: =03_Categorías!M10 -> 2
A22: 7 | B22: Café Clásico | C22: =03_Categorías!M11 -> 7
A23: 8 | B23: Café Frío | C23: =03_Categorías!M12 -> 3
A24: 9 | B24: Batidos & Jugos | C24: =03_Categorías!M13 -> 6
A25: 10 | B25: Adicionales | C25: =03_Categorías!M14 -> 2
A26: 11 | B26: Sin TACC | C26: =03_Categorías!M15 -> 4
A27: 12 | B27: Tortas & Tartas | C27: =03_Categorías!M16 -> 7
A28: 13 | B28: Sándwiches & Tostones | C28: =03_Categorías!M17 -> 5
A31: CÓMO USAR ESTE ARCHIVO (guía rápida)
A32: Convención de colores | B32: Amarillo = lo cargás vos · Naranja = dice «Verificar»: confirmalo y elegí Sí/No · Sin color = se calcula solo.
A33: Para publicar el menú | B33: Solo necesitás tres hojas: 01 (nombres y textos), 02 (qué se muestra y en qué orden) y 04 (precios).
A34: 01_Menú_Multilingüe | B34: Los textos en 5 idiomas. Si editás, mirá que la columna «Estado de traducción» siga en «Completa».
A35: 02_Productos_MASTER | B35: El interruptor de cada producto: activo, destacado, recomendado, nuevo. Todo con desplegable Sí/No.
A36: 03_Categorías | B36: El orden y nombre de las secciones del menú. Casi nunca se toca.
A37: 04_Precios | B37: Cargá precio local y costo (amarillo). El resto (USD, margen, fecha) se calcula solo.
A38: 05 a 08 | B38: Ficha operativa, ingredientes, alérgenos y personalización. Andá reemplazando los «Verificar» con desplegables.
A39: 09_Ingeniería_Menú | B39: Se llena sola con precios (04) y ventas (12). Clasifica: Estrella / Caballo / Incógnita / Perro.
A40: 10 a 12 | B40: Fotos y SEO, canales de publicación y estadísticas. Para más adelante; no bloquean el menú.
A41: 13_Configuración | B41: Datos generales: tipo de cambio (amarillo), WhatsApp, Instagram, dirección.
A42: Ordenar y filtrar | B42: Podés ordenar o filtrar tranquilo: las fórmulas buscan por ID, no por posición de fila.

Sheet 01_Menú_Multilingüe
A1: Menú multilingüe · Amelí Casa de Té & Brunch
A2: Base editorial principal para el menú QR. Las traducciones están localizadas para turistas y preservan los nombres propios cuando aportan identidad.
A4: ID | B4: Categoría | C4: Orden | D4: Nombre ES-AR | E4: Nombre EN-UK | F4: Nombre PT-BR | G4: Nombre FR-FR | H4: Nombre IT-IT | I4: Descripción ES-AR | J4: Descripción EN-UK | K4: Descripción PT-BR | L4: Descripción FR-FR | M4: Descripción IT-IT | N4: Estado de traducción
A5: DYM001 | B5: Desayunos & Meriendas | C5: 1 | D5: Avocado | E5: Avocado Breakfast | F5: Café da manhã com abacate | G5: Petit-déjeuner à l’avocat | H5: Colazione con avocado | I5: Bowl de huevos revueltos y palta, acompañado de dos tostadas, queso crema, café o té y un vaso pequeño de jugo de naranja. | J5: A bowl of scrambled eggs and avocado, served with two slices of toast, cream cheese, coffee or tea, and a small glass of orange juice. | K5: Bowl de ovos mexidos com abacate, acompanhado de duas torradas, cream cheese, café ou chá e um pequeno copo de suco de laranja. | L5: Bol d’œufs brouillés et d’avocat, accompagné de deux toasts, de fromage frais, d’un café ou d’un thé et d’un petit verre de jus d’orange. | M5: Bowl con uova strapazzate e avocado, accompagnato da due fette di pane tostato, formaggio spalmabile, caffè o tè e un piccolo bicchiere di succo d’arancia. | N5: =IF(COUNTA(D5:M5)=10,"Completa","Revisar") -> Completa
A6: DYM002 | B6: Desayunos & Meriendas | C6: 2 | D6: Desayuno clásico | E6: Classic Breakfast | F6: Café da manhã clássico | G6: Petit-déjeuner classique | H6: Colazione classica | I6: Dos tostadas con queso crema y mermelada, acompañadas de café o té y un vaso pequeño de jugo de naranja. | J6: Two slices of toast with cream cheese and jam, served with coffee or tea and a small glass of orange juice. | K6: Duas torradas com cream cheese e geleia, acompanhadas de café ou chá e um pequeno copo de suco de laranja. | L6: Deux toasts avec fromage frais et confiture, accompagnés d’un café ou d’un thé et d’un petit verre de jus d’orange. | M6: Due fette di pane tostato con formaggio spalmabile e confettura, accompagnate da caffè o tè e da un piccolo bicchiere di succo d’arancia. | N6: =IF(COUNTA(D6:M6)=10,"Completa","Revisar") -> Completa
A7: DYM003 | B7: Desayunos & Meriendas | C7: 3 | D7: Desayuno mendocino | E7: Mendoza Breakfast | F7: Café da manhã mendocino | G7: Petit-déjeuner mendocin | H7: Colazione mendocina | I7: Dos raspaditas mendocinas, acompañadas de café o té y un vaso pequeño de jugo de naranja. | J7: Two traditional Mendoza raspaditas, served with coffee or tea and a small glass of orange juice. | K7: Duas raspaditas tradicionais de Mendoza, acompanhadas de café ou chá e um pequeno copo de suco de laranja. | L7: Deux raspaditas traditionnelles de Mendoza, accompagnées d’un café ou d’un thé et d’un petit verre de jus d’orange. | M7: Due raspaditas tradizionali di Mendoza, accompagnate da caffè o tè e da un piccolo bicchiere di succo d’arancia. | N7: =IF(COUNTA(D7:M7)=10,"Completa","Revisar") -> Completa
A8: DYM004 | B8: Desayunos & Meriendas | C8: 4 | D8: Desayuno saludable | E8: Healthy Breakfast | F8: Café da manhã saudável | G8: Petit-déjeuner équilibré | H8: Colazione salutare | I8: Yogur con frutas de estación, granola, frutos secos, miel y coco, acompañado de café o té y un vaso pequeño de jugo de naranja. | J8: Yoghurt with seasonal fruit, granola, nuts, honey and coconut, served with coffee or tea and a small glass of orange juice. | K8: Iogurte com frutas da estação, granola, castanhas, mel e coco, acompanhado de café ou chá e um pequeno copo de suco de laranja. | L8: Yaourt aux fruits de saison, granola, fruits à coque, miel et noix de coco, accompagné d’un café ou d’un thé et d’un petit verre de jus d’orange. | M8: Yogurt con frutta di stagione, granola, frutta secca, miele e cocco, accompagnato da caffè o tè e da un piccolo bicchiere di succo d’arancia. | N8: =IF(COUNTA(D8:M8)=10,"Completa","Revisar") -> Completa
A9: DEL001 | B9: Delicias | C9: 1 | D9: Bowl de huevos | E9: Egg Bowl | F9: Bowl de ovos | G9: Bowl d’œufs | H9: Bowl di uova | I9: Huevos preparados al momento y servidos en bowl. Consultar los acompañamientos disponibles. | J9: Eggs cooked to order and served in a bowl. Please ask about the available accompaniments. | K9: Ovos preparados na hora e servidos em bowl. Consulte os acompanhamentos disponíveis. | L9: Œufs préparés à la demande et servis dans un bol. Merci de consulter les accompagnements disponibles. | M9: Uova preparate al momento e servite in bowl. Chiedere quali accompagnamenti sono disponibili. | N9: =IF(COUNTA(D9:M9)=10,"Completa","Revisar") -> Completa
A10: DEL002 | B10: Delicias | C10: 2 | D10: Bowl de frutas | E10: Seasonal Fruit Bowl | F10: Bowl de frutas da estação | G10: Bol de fruits de saison | H10: Bowl di frutta di stagione | I10: Selección de frutas frescas de estación, servidas en bowl. | J10: A selection of fresh seasonal fruit, served in a bowl. | K10: Seleção de frutas frescas da estação, servidas em bowl. | L10: Sélection de fruits frais de saison, servis dans un bol. | M10: Selezione di frutta fresca di stagione, servita in bowl. | N10: =IF(COUNTA(D10:M10)=10,"Completa","Revisar") -> Completa
A11: DEL003 | B11: Delicias | C11: 3 | D11: Chipá | E11: Chipá Cheese Rolls | F11: Pão de queijo tipo chipá | G11: Petits pains au fromage chipá | H11: Panini al formaggio chipá | I11: Panecillos de almidón de mandioca y queso, suaves por dentro y ligeramente crocantes por fuera. | J11: Cheese rolls made with cassava starch, soft inside and lightly crisp outside. | K11: Pãezinhos de polvilho e queijo, macios por dentro e levemente crocantes por fora. | L11: Petits pains au fromage à base de fécule de manioc, moelleux à l’intérieur et légèrement croustillants à l’extérieur. | M11: Panini al formaggio preparati con amido di manioca, morbidi all’interno e leggermente croccanti fuori. | N11: =IF(COUNTA(D11:M11)=10,"Completa","Revisar") -> Completa
A12: DEL004 | B12: Delicias | C12: 4 | D12: Medialunas | E12: Argentine Croissants | F12: Medialunas argentinas | G12: Croissants argentins | H12: Cornetti argentini | I12: Medialunas argentinas suaves y hojaldradas. Consultar presentación y cantidad por porción. | J12: Soft, flaky Argentine croissants. Please ask about serving size and presentation. | K12: Medialunas argentinas macias e folhadas. Consulte a quantidade e a apresentação da porção. | L12: Croissants argentins moelleux et feuilletés. Merci de consulter la quantité et la présentation. | M12: Cornetti argentini soffici e sfogliati. Chiedere quantità e presentazione della porzione. | N12: =IF(COUNTA(D12:M12)=10,"Completa","Revisar") -> Completa
A13: DEL005 | B13: Delicias | C13: 5 | D13: Mini budines | E13: Mini Loaf Cakes | F13: Mini bolos tipo inglês | G13: Mini cakes | H13: Mini plumcake | I13: Selección de mini budines artesanales. Consultar los sabores disponibles del día. | J13: A selection of handmade mini loaf cakes. Please ask about today’s available flavours. | K13: Seleção de mini bolos artesanais. Consulte os sabores disponíveis do dia. | L13: Sélection de mini cakes artisanaux. Merci de demander les parfums disponibles du jour. | M13: Selezione di mini plumcake artigianali. Chiedere i gusti disponibili del giorno. | N13: =IF(COUNTA(D13:M13)=10,"Completa","Revisar") -> Completa
A14: DEL006 | B14: Delicias | C14: 6 | D14: Raspaditas mendocinas | E14: Mendoza Raspaditas | F14: Raspaditas mendocinas | G14: Raspaditas de Mendoza | H14: Raspaditas mendocine | I14: Tortitas saladas tradicionales de Mendoza, de textura firme, ideales para acompañar café, té o mate. | J14: Traditional savoury baked rounds from Mendoza, with a firm texture and perfect alongside coffee, tea or mate. | K14: Tortinhas salgadas tradicionais de Mendoza, de textura firme, ideais para acompanhar café, chá ou mate. | L14: Petites galettes salées traditionnelles de Mendoza, à la texture ferme, idéales avec un café, un thé ou du maté. | M14: Focaccine salate tradizionali di Mendoza, dalla consistenza compatta, ideali con caffè, tè o mate. | N14: =IF(COUNTA(D14:M14)=10,"Completa","Revisar") -> Completa
A15: DEL007 | B15: Delicias | C15: 7 | D15: Smoothie bowl | E15: Smoothie Bowl | F15: Smoothie bowl | G15: Smoothie bowl | H15: Smoothie bowl | I15: Base cremosa de frutas servida en bowl con toppings. Consultar la combinación disponible del día. | J15: A creamy fruit base served in a bowl with toppings. Please ask about today’s available combination. | K15: Base cremosa de frutas servida em bowl com toppings. Consulte a combinação disponível do dia. | L15: Base crémeuse de fruits servie dans un bol avec garnitures. Merci de demander la composition disponible du jour. | M15: Base cremosa di frutta servita in bowl con topping. Chiedere la combinazione disponibile del giorno. | N15: =IF(COUNTA(D15:M15)=10,"Completa","Revisar") -> Completa
A16: TEH001 | B16: Té en Hebras | C16: 1 | D16: Selección de té en hebras | E16: Loose-Leaf Tea Selection | F16: Seleção de chás de folhas soltas | G16: Sélection de thés en feuilles | H16: Selezione di tè in foglia | I16: Té negro, pu-erh o verde, preparado en hebras. | J16: Black, pu-erh or green tea, brewed from loose leaves. | K16: Chá preto, pu-erh ou verde, preparado com folhas soltas. | L16: Thé noir, pu-erh ou vert, préparé en feuilles. | M16: Tè nero, pu-erh o verde, preparato con foglie sfuse. | N16: =IF(COUNTA(D16:M16)=10,"Completa","Revisar") -> Completa
... A59: SAT005 | B59: Sándwiches & Tostones | C59: 5 | D59: Pistachero | E59: Pistachio Mortadella Sandwich | F59: Sanduíche de mortadela e pistache | G59: Sandwich mortadelle & pistache | H59: Panino mortadella & pistacchio | I59: Sándwich de mortadela, queso, manteca especiada, pistacho y queso gratinado. | J59: A sandwich with mortadella, cheese, spiced butter, pistachios and melted cheese. | K59: Sanduíche com mortadela, queijo, manteiga temperada, pistache e queijo gratinado. | L59: Sandwich à la mortadelle, au fromage, au beurre épicé, aux pistaches et au fromage gratiné. | M59: Panino con mortadella, formaggio, burro speziato, pistacchi e formaggio gratinato. | N59: =IF(COUNTA(D59:M59)=10,"Completa","Revisar") -> Completa

Sheet 02_Productos_MASTER
A1: Productos MASTER · Fuente única del menú
A2: Gobierna el orden, estado y señalización comercial de cada producto. «Más vendido» debe completarse únicamente con datos reales.
A4: ID | B4: SKU | C4: Grupo principal | D4: Categoría | E4: Código categoría | F4: Orden categoría | G4: Orden producto | H4: Orden global | I4: Página fuente | J4: Producto activo | K4: Destacado editorial | L4: Recomendado | M4: Más vendido | N4: Nuevo | O4: Edición limitada | P4: Etiqueta inicial | Q4: Observaciones
A5: DYM001 | B5: DYM001 | C5: Desayunos & Brunch | D5: Desayunos & Meriendas | E5: DYM | F5: 1 | G5: 1 | H5: =(F5*100)+G5 -> 101 | I5: 2 | J5: Sí | K5: Sí | L5: Sí | M5: No | N5: No | O5: No | P5: Recomendado Amelí
A6: DYM002 | B6: DYM002 | C6: Desayunos & Brunch | D6: Desayunos & Meriendas | E6: DYM | F6: 1 | G6: 2 | H6: =(F6*100)+G6 -> 102 | I6: 2 | J6: Sí | K6: No | L6: No | M6: No | N6: No | O6: No
A7: DYM003 | B7: DYM003 | C7: Desayunos & Brunch | D7: Desayunos & Meriendas | E7: DYM | F7: 1 | G7: 3 | H7: =(F7*100)+G7 -> 103 | I7: 2 | J7: Sí | K7: No | L7: Sí | M7: No | N7: No | O7: No | P7: Identidad mendocina
A8: DYM004 | B8: DYM004 | C8: Desayunos & Brunch | D8: Desayunos & Meriendas | E8: DYM | F8: 1 | G8: 4 | H8: =(F8*100)+G8 -> 104 | I8: 2 | J8: Sí | K8: No | L8: Sí | M8: No | N8: No | O8: No | P8: Opción equilibrada
A9: DEL001 | B9: DEL001 | C9: Desayunos & Brunch | D9: Delicias | E9: DEL | F9: 2 | G9: 1 | H9: =(F9*100)+G9 -> 201 | I9: 2 | J9: Sí | K9: No | L9: No | M9: No | N9: No | O9: No | Q9: Confirmar receta y acompañamientos.
A10: DEL002 | B10: DEL002 | C10: Desayunos & Brunch | D10: Delicias | E10: DEL | F10: 2 | G10: 2 | H10: =(F10*100)+G10 -> 202 | I10: 2 | J10: Sí | K10: No | L10: No | M10: No | N10: No | O10: No
A11: DEL003 | B11: DEL003 | C11: Desayunos & Brunch | D11: Delicias | E11: DEL | F11: 2 | G11: 3 | H11: =(F11*100)+G11 -> 203 | I11: 2 | J11: Sí | K11: No | L11: No | M11: No | N11: No | O11: No
A12: DEL004 | B12: DEL004 | C12: Desayunos & Brunch | D12: Delicias | E12: DEL | F12: 2 | G12: 4 | H12: =(F12*100)+G12 -> 204 | I12: 2 | J12: Sí | K12: No | L12: No | M12: No | N12: No | O12: No
A13: DEL005 | B13: DEL005 | C13: Desayunos & Brunch | D13: Delicias | E13: DEL | F13: 2 | G13: 5 | H13: =(F13*100)+G13 -> 205 | I13: 2 | J13: Sí | K13: No | L13: No | M13: No | N13: No | O13: No | Q13: Los ingredientes varían según el sabor.
A14: DEL006 | B14: DEL006 | C14: Desayunos & Brunch | D14: Delicias | E14: DEL | F14: 2 | G14: 6 | H14: =(F14*100)+G14 -> 206 | I14: 2 | J14: Sí | K14: No | L14: No | M14: No | N14: No | O14: No | P14: Especialidad regional
A15: DEL007 | B15: DEL007 | C15: Desayunos & Brunch | D15: Delicias | E15: DEL | F15: 2 | G15: 7 | H15: =(F15*100)+G15 -> 207 | I15: 2 | J15: Sí | K15: No | L15: No | M15: No | N15: No | O15: No | Q15: Confirmar ingredientes, toppings y base líquida.
A16: TEH001 | B16: TEH001 | C16: Té & Infusiones | D16: Té en Hebras | E16: TEH | F16: 3 | G16: 1 | H16: =(F16*100)+G16 -> 301 | I16: 2 | J16: Sí | K16: No | L16: No | M16: No | N16: No | O16: No
A17: TIS001 | B17: TIS001 | C17: Té & Infusiones | D17: Tisanas | E17: TIS | F17: 4 | G17: 1 | H17: =(F17*100)+G17 -> 401 | I17: 2 | J17: Sí | K17: No | L17: No | M17: No | N17: No | O17: No
A18: TIS002 | B18: TIS002 | C18: Té & Infusiones | D18: Tisanas | E18: TIS | F18: 4 | G18: 2 | H18: =(F18*100)+G18 -> 402 | I18: 2 | J18: Sí | K18: No | L18: No | M18: No | N18: No | O18: No
A19: TIS003 | B19: TIS003 | C19: Té & Infusiones | D19: Tisanas | E19: TIS | F19: 4 | G19: 3 | H19: =(F19*100)+G19 -> 403 | I19: 2 | J19: Sí | K19: No | L19: No | M19: No | N19: No | O19: No
A20: BLE001 | B20: BLE001 | C20: Té & Infusiones | D20: Blends | E20: BLE | F20: 5 | G20: 1 | H20: =(F20*100)+G20 -> 501 | I20: 2 | J20: Sí | K20: Sí | L20: Sí | M20: No | N20: No | O20: No | P20: Blend de la casa
A21: BLE002 | B21: BLE002 | C21: Té & Infusiones | D21: Blends | E21: BLE | F21: 5 | G21: 2 | H21: =(F21*100)+G21 -> 502 | I21: 2 | J21: Sí | K21: No | L21: No | M21: No | N21: No | O21: No
A22: BLE003 | B22: BLE003 | C22: Té & Infusiones | D22: Blends | E22: BLE | F22: 5 | G22: 3 | H22: =(F22*100)+G22 -> 503 | I22: 2 | J22: Sí | K22: No | L22: No | M22: No | N22: No | O22: No
A23: BLE004 | B23: BLE004 | C23: Té & Infusiones | D23: Blends | E23: BLE | F23: 5 | G23: 4 | H23: =(F23*100)+G23 -> 504 | I23: 2 | J23: Sí | K23: No | L23: No | M23: No | N23: No | O23: No
A24: ESP001 | B24: ESP001 | C24: Té & Infusiones | D24: Especiales | E24: ESP | F24: 6 | G24: 1 | H24: =(F24*100)+G24 -> 601 | I24: 2 | J24: Sí | K24: No | L24: No | M24: No | N24: No | O24: No
A25: ESP002 | B25: ESP002 | C25: Té & Infusiones | D25: Especiales | E25: ESP | F25: 6 | G25: 2 | H25: =(F25*100)+G25 -> 602 | I25: 2 | J25: Sí | K25: Sí | L25: Sí | M25: No | N25: No | O25: No | P25: Especialidad Amelí
A26: CCL001 | B26: CCL001 | C26: Cafetería | D26: Café Clásico | E26: CCL | F26: 7 | G26: 1 | H26: =(F26*100)+G26 -> 701 | I26: 3 | J26: Sí | K26: No | L26: No | M26: No | N26: No | O26: No
A27: CCL002 | B27: CCL002 | C27: Cafetería | D27: Café Clásico | E27: CCL | F27: 7 | G27: 2 | H27: =(F27*100)+G27 -> 702 | I27: 3 | J27: Sí | K27: No | L27: No | M27: No | N27: No | O27: No
A28: CCL003 | B28: CCL003 | C28: Cafetería | D28: Café Clásico | E28: CCL | F28: 7 | G28: 3 | H28: =(F28*100)+G28 -> 703 | I28: 3 | J28: Sí | K28: No | L28: No | M28: No | N28: No | O28: No
A29: CCL004 | B29: CCL004 | C29: Cafetería | D29: Café Clásico | E29: CCL | F29: 7 | G29: 4 | H29: =(F29*100)+G29 -> 704 | I29: 3 | J29: Sí | K29: No | L29: No | M29: No | N29: No | O29: No
A30: CCL005 | B30: CCL005 | C30: Cafetería | D30: Café Clásico | E30: CCL | F30: 7 | G30: 5 | H30: =(F30*100)+G30 -> 705 | I30: 3 | J30: Sí | K30: No | L30: No | M30: No | N30: No | O30: No
A31: CCL006 | B31: CCL006 | C31: Cafetería | D31: Café Clásico | E31: CCL | F31: 7 | G31: 6 | H31: =(F31*100)+G31 -> 706 | I31: 3 | J31: Sí | K31: No | L31: No | M31: No | N31: No | O31: No
A32: CCL007 | B32: CCL007 | C32: Cafetería | D32: Café Clásico | E32: CCL | F32: 7 | G32: 7 | H32: =(F32*100)+G32 -> 707 | I32: 3 | J32: Sí | K32: No | L32: Sí | M32: No | N32: No | O32: No
A33: CFR001 | B33: CFR001 | C33: Cafetería | D33: Café Frío | E33: CFR | F33: 8 | G33: 1 | H33: =(F33*100)+G33 -> 801 | I33: 3 | J33: Sí | K33: No | L33: No | M33: No | N33: No | O33: No
A34: CFR002 | B34: CFR002 | C34: Cafetería | D34: Café Frío | E34: CFR | F34: 8 | G34: 2 | H34: =(F34*100)+G34 -> 802 | I34: 3 | J34: Sí | K34: No | L34: No | M34: No | N34: No | O34: No
A35: CFR003 | B35: CFR003 | C35: Cafetería | D35: Café Frío | E35: CFR | F35: 8 | G35: 3 | H35: =(F35*100)+G35 -> 803 | I35: 3 | J35: Sí | K35: Sí | L35: Sí | M35: No | N35: No | O35: No | P35: Favorito dulce
A36: BYJ001 | B36: BYJ001 | C36: Bebidas Frías | D36: Batidos & Jugos | E36: BYJ | F36: 9 | G36: 1 | H36: =(F36*100)+G36 -> 901 | I36: 3 | J36: Sí | K36: No | L36: No | M36: No | N36: No | O36: No | Q36: Confirmar si la base contiene leche.
A37: BYJ002 | B37: BYJ002 | C37: Bebidas Frías | D37: Batidos & Jugos | E37: BYJ | F37: 9 | G37: 2 | H37: =(F37*100)+G37 -> 902 | I37: 3 | J37: Sí | K37: No | L37: No | M37: No | N37: No | O37: No
A38: BYJ003 | B38: BYJ003 | C38: Bebidas Frías | D38: Batidos & Jugos | E38: BYJ | F38: 9 | G38: 3 | H38: =(F38*100)+G38 -> 903 | I38: 3 | J38: Sí | K38: No | L38: No | M38: No | N38: No | O38: No
A39: BYJ004 | B39: BYJ004 | C39: Bebidas Frías | D39: Batidos & Jugos | E39: BYJ | F39: 9 | G39: 4 | H39: =(F39*100)+G39 -> 904 | I39: 3 | J39: Sí | K39: No | L39: No | M39: No | N39: No | O39: No
A40: BYJ005 | B40: BYJ005 | C40: Bebidas Frías | D40: Batidos & Jugos | E40: BYJ | F40: 9 | G40: 5 | H40: =(F40*100)+G40 -> 905 | I40: 3 | J40: Sí | K40: No | L40: No | M40: No | N40: No | O40: No
A41: BYJ006 | B41: BYJ006 | C41: Bebidas Frías | D41: Batidos & Jugos | E41: BYJ | F41: 9 | G41: 6 | H41: =(F41*100)+G41 -> 906 | I41: 3 | J41: Sí | K41: No | L41: Sí | M41: No | N41: No | O41: No
...

Sheet 03_Categorías
A1: Arquitectura de categorías · Jerarquía multilingüe
A2: La columna «Orden» controla la navegación del menú mobile-first. Los grupos permiten mostrar una portada breve sin perder profundidad.
A4: Código | B4: Orden | C4: Grupo ES | D4: Grupo EN | E4: Grupo PT | F4: Grupo FR | G4: Grupo IT | H4: Categoría ES | I4: Categoría EN | J4: Categoría PT | K4: Categoría FR | L4: Categoría IT | M4: Cantidad de productos | N4: Página fuente | O4: Visible
A5: DYM | B5: 1 | C5: Desayunos & Brunch | D5: Breakfast & Brunch | E5: Café da manhã & brunch | F5: Petit-déjeuner & brunch | G5: Colazione & brunch | H5: Desayunos & Meriendas | I5: Breakfast & Afternoon Tea | J5: Café da manhã & lanche da tarde | K5: Petit-déjeuner & goûter | L5: Colazione & merenda | M5: =COUNTIF(02_Productos_MASTER!$E$5:$E$59,A5) -> 4 | N5: 2 | O5: Sí
A6: DEL | B6: 2 | C6: Desayunos & Brunch | D6: Breakfast & Brunch | E6: Café da manhã & brunch | F6: Petit-déjeuner & brunch | G6: Colazione & brunch | H6: Delicias | I6: Bakery & Light Bites | J6: Delícias & lanches leves | K6: Douceurs & petites bouchées | L6: Delizie & spuntini | M6: =COUNTIF(02_Productos_MASTER!$E$5:$E$59,A6) -> 7 | N6: 2 | O6: Sí
A7: TEH | B7: 3 | C7: Té & Infusiones | D7: Tea & Infusions | E7: Chás & infusões | F7: Thés & infusions | G7: Tè & infusi | H7: Té en Hebras | I7: Loose-Leaf Tea | J7: Chás de folhas soltas | K7: Thés en feuilles | L7: Tè in foglia | M7: =COUNTIF(02_Productos_MASTER!$E$5:$E$59,A7) -> 1 | N7: 2 | O7: Sí
A8: TIS | B8: 4 | C8: Té & Infusiones | D8: Tea & Infusions | E8: Chás & infusões | F8: Thés & infusions | G8: Tè & infusi | H8: Tisanas | I8: Herbal Infusions | J8: Infusões de ervas | K8: Tisanes | L8: Tisane | M8: =COUNTIF(02_Productos_MASTER!$E$5:$E$59,A8) -> 3 | N8: 2 | O8: Sí
A9: BLE | B9: 5 | C9: Té & Infusiones | D9: Tea & Infusions | E9: Chás & infusões | F9: Thés & infusions | G9: Tè & infusi | H9: Blends | I9: Signature Tea Blends | J9: Blends autorais | K9: Mélanges signature | L9: Miscele d’autore | M9: =COUNTIF(02_Productos_MASTER!$E$5:$E$59,A9) -> 4 | N9: 2 | O9: Sí
A10: ESP | B10: 6 | C10: Té & Infusiones | D10: Tea & Infusions | E10: Chás & infusões | F10: Thés & infusions | G10: Tè & infusi | H10: Especiales | I10: Hot Specialities | J10: Especialidades quentes | K10: Spécialités chaudes | L10: Specialità calde | M10: =COUNTIF(02_Productos_MASTER!$E$5:$E$59,A10) -> 2 | N10: 2 | O10: Sí
A11: CCL | B11: 7 | C11: Cafetería | D11: Coffee | E11: Cafeteria | F11: Café | G11: Caffetteria | H11: Café Clásico | I11: Classic Coffee | J11: Cafés clássicos | K11: Cafés classiques | L11: Caffè classici | M11: =COUNTIF(02_Productos_MASTER!$E$5:$E$59,A11) -> 7 | N11: 3 | O11: Sí
A12: CFR | B12: 8 | C12: Cafetería | D12: Coffee | E12: Cafeteria | F12: Café | G12: Caffetteria | H12: Café Frío | I12: Iced Coffee | J12: Cafés gelados | K12: Cafés glacés | L12: Caffè freddi | M12: =COUNTIF(02_Productos_MASTER!$E$5:$E$59,A12) -> 3 | N12: 3 | O12: Sí
A13: BYJ | B13: 9 | C13: Bebidas Frías | D13: Cold Drinks | E13: Bebidas frias | F13: Boissons fraîches | G13: Bevande fredde | H13: Batidos & Jugos | I13: Smoothies & Juices | J13: Vitaminas & sucos | K13: Smoothies & jus | L13: Frullati & succhi | M13: =COUNTIF(02_Productos_MASTER!$E$5:$E$59,A13) -> 6 | N13: 3 | O13: Sí
A14: ADI | B14: 10 | C14: Personalización | D14: Customisation | E14: Personalização | F14: Personnalisation | G14: Personalizzazione | H14: Adicionales | I14: Milk Options | J14: Opções de leite | K14: Options de lait | L14: Opzioni latte | M14: =COUNTIF(02_Productos_MASTER!$E$5:$E$59,A14) -> 2 | N14: 3 | O14: Sí
A15: STC | B15: 11 | C15: Sin TACC | D15: Gluten-Free | E15: Sem glúten | F15: Sans gluten | G15: Senza glutine | H15: Sin TACC | I15: Gluten-Free Selection | J15: Seleção sem glúten | K15: Sélection sans gluten | L15: Selezione senza glutine | M15: =COUNTIF(02_Productos_MASTER!$E$5:$E$59,A15) -> 4 | N15: 3 | O15: Sí
A16: TYT | B16: 12 | C16: Pastelería | D16: Cakes & Pastries | E16: Bolos & tortas | F16: Gâteaux & tartes | G16: Torte & dolci | H16: Tortas & Tartas | I16: Cakes & Tarts | J16: Bolos & tortas | K16: Gâteaux & tartes | L16: Torte & crostate | M16: =COUNTIF(02_Productos_MASTER!$E$5:$E$59,A16) -> 7 | N16: 4 | O16: Sí
A17: SAT | B17: 13 | C17: Salados | D17: Savoury | E17: Salgados | F17: Salé | G17: Salati | H17: Sándwiches & Tostones | I17: Sandwiches & Open Toasts | J17: Sanduíches & tostadas | K17: Sandwichs & tartines | L17: Panini & bruschette | M17: =COUNTIF(02_Productos_MASTER!$E$5:$E$59,A17) -> 5 | N17: 4 | O17: Sí

Sheet 04_Precios
A1: Precios y rentabilidad básica
A2: Completar únicamente las celdas crema. El precio en USD, el margen bruto y el estado de carga se calculan automáticamente.
A4: ID | B4: Producto ES-AR | C4: Moneda | D4: Precio local | E4: Precio delivery | F4: Precio promocional | G4: Precio de referencia USD | H4: Costo unitario | I4: Margen bruto | J4: Margen bruto % | K4: IVA incluido | L4: Fecha actualización | M4: Estado de carga | N4: Observaciones
A5: DYM001 | B5: Avocado | C5: ARS | G5: =IF(OR(D5="",TC_USD=""),"",D5/TC_USD) | I5: =IF(OR(D5="",H5=""),"",D5-H5) | J5: =IFERROR(I5/D5,"") | K5: Sí | L5: =IF(D5="","",TODAY()) | M5: =IF(D5="","Pendiente",IF(H5="","Precio cargado; falta costo","Completo")) -> Pendiente
A6: DYM002 | B6: Desayuno clásico | C6: ARS | G6: =IF(OR(D6="",TC_USD=""),"",D6/TC_USD) | I6: =IF(OR(D6="",H6=""),"",D6-H6) | J6: =IFERROR(I6/D6,"") | K6: Sí | L6: =IF(D6="","",TODAY()) | M6: =IF(D6="","Pendiente",IF(H6="","Precio cargado; falta costo","Completo")) -> Pendiente
A7: DYM003 | B7: Desayuno mendocino | C7: ARS | G7: =IF(OR(D7="",TC_USD=""),"",D7/TC_USD) | I7: =IF(OR(D7="",H7=""),"",D7-H7) | J7: =IFERROR(I7/D7,"") | K7: Sí | L7: =IF(D7="","",TODAY()) | M7: =IF(D7="","Pendiente",IF(H7="","Precio cargado; falta costo","Completo")) -> Pendiente
A8: DYM004 | B8: Desayuno saludable | C8: ARS | G8: =IF(OR(D8="",TC_USD=""),"",D8/TC_USD) | I8: =IF(OR(D8="",H8=""),"",D8-H8) | J8: =IFERROR(I8/D8,"") | K8: Sí | L8: =IF(D8="","",TODAY()) | M8: =IF(D8="","Pendiente",IF(H8="","Precio cargado; falta costo","Completo")) -> Pendiente
A9: DEL001 | B9: Bowl de huevos | C9: ARS | G9: =IF(OR(D9="",TC_USD=""),"",D9/TC_USD) | I9: =IF(OR(D9="",H9=""),"",D9-H9) | J9: =IFERROR(I9/D9,"") | K9: Sí | L9: =IF(D9="","",TODAY()) | M9: =IF(D9="","Pendiente",IF(H9="","Precio cargado; falta costo","Completo")) -> Pendiente
A10: DEL002 | B10: Bowl de frutas | C10: ARS | G10: =IF(OR(D10="",TC_USD=""),"",D10/TC_USD) | I10: =IF(OR(D10="",H10=""),"",D10-H10) | J10: =IFERROR(I10/D10,"") | K10: Sí | L10: =IF(D10="","",TODAY()) | M10: =IF(D10="","Pendiente",IF(H10="","Precio cargado; falta costo","Completo")) -> Pendiente
A11: DEL003 | B11: Chipá | C11: ARS | G11: =IF(OR(D11="",TC_USD=""),"",D11/TC_USD) | I11: =IF(OR(D11="",H11=""),"",D11-H11) | J11: =IFERROR(I11/D11,"") | K11: Sí | L11: =IF(D11="","",TODAY()) | M11: =IF(D11="","Pendiente",IF(H11="","Precio cargado; falta costo","Completo")) -> Pendiente
A12: DEL004 | B12: Medialunas | C12: ARS | G12: =IF(OR(D12="",TC_USD=""),"",D12/TC_USD) | I12: =IF(OR(D12="",H12=""),"",D12-H12) | J12: =IFERROR(I12/D12,"") | K12: Sí | L12: =IF(D12="","",TODAY()) | M12: =IF(D12="","Pendiente",IF(H12="","Precio cargado; falta costo","Completo")) -> Pendiente
A13: DEL005 | B13: Mini budines | C13: ARS | G13: =IF(OR(D13="",TC_USD=""),"",D13/TC_USD) | I13: =IF(OR(D13="",H13=""),"",D13-H13) | J13: =IFERROR(I13/D13,"") | K13: Sí | L13: =IF(D13="","",TODAY()) | M13: =IF(D13="","Pendiente",IF(H13="","Precio cargado; falta costo","Completo")) -> Pendiente
A14: DEL006 | B14: Raspaditas mendocinas | C14: ARS | G14: =IF(OR(D14="",TC_USD=""),"",D14/TC_USD) | I14: =IF(OR(D14="",H14=""),"",D14-H14) | J14: =IFERROR(I14/D14,"") | K14: Sí | L14: =IF(D14="","",TODAY()) | M14: =IF(D14="","Pendiente",IF(H14="","Precio cargado; falta costo","Completo")) -> Pendiente
A15: DEL007 | B15: Smoothie bowl | C15: ARS | G15: =IF(OR(D15="",TC_USD=""),"",D15/TC_USD) | I15: =IF(OR(D15="",H15=""),"",D15-H15) | J15: =IFERROR(I15/D15,"") | K15: Sí | L15: =IF(D15="","",TODAY()) | M15: =IF(D15="","Pendiente",IF(H15="","Precio cargado; falta costo","Completo")) -> Pendiente
A16: TEH001 | B16: Selección de té en hebras | C16: ARS | G16: =IF(OR(D16="",TC_USD=""),"",D16/TC_USD) | I16: =IF(OR(D16="",H16=""),"",D16-H16) | J16: =IFERROR(I16/D16,"") | K16: Sí | L16: =IF(D16="","",TODAY()) | M16: =IF(D16="","Pendiente",IF(H16="","Precio cargado; falta costo","Completo")) -> Pendiente
... A59: SAT005 | B59: Pistachero | C59: ARS | G59: =IF(OR(D59="",TC_USD=""),"",D59/TC_USD) | I59: =IF(OR(D59="",H59=""),"",D59-H59) | J59: =IFERROR(I59/D59,"") | K59: Sí | L59: =IF(D59="","",TODAY()) | M59: =IF(D59="","Pendiente",IF(H59="","Precio cargado; falta costo","Completo")) -> Pendiente

Sheet 05_Gastronomía
A1: Información gastronómica y operativa
A2: Los campos «Verificar» deben validarse con cocina y proveedores antes de publicar o automatizar el menú.
A4: ID | B4: Producto ES-AR | C4: Tipo | D4: Temperatura | E4: Formato de servicio | F4: Porciones | G4: Tiempo de preparación (min) | H4: Origen | I4: Elaboración propia | J4: Producto tercerizado | K4: Disponible para llevar | L4: Notas operativas
A5: DYM001 | B5: Avocado | C5: Combo de desayuno | D5: Mixta | E5: Porción individual | F5: 1 | I5: Verificar | J5: Verificar | K5: Verificar
A6: DYM002 | B6: Desayuno clásico | C6: Combo de desayuno | D6: Mixta | E6: Porción individual | F6: 1 | I6: Verificar | J6: Verificar | K6: Verificar
A7: DYM003 | B7: Desayuno mendocino | C7: Combo de desayuno regional | D7: Mixta | E7: Porción individual | F7: 1 | H7: Mendoza, Argentina | I7: Verificar | J7: Verificar | K7: Verificar
A8: DYM004 | B8: Desayuno saludable | C8: Combo de desayuno | D8: Mixta | E8: Porción individual | F8: 1 | I8: Verificar | J8: Verificar | K8: Verificar
A9: DEL001 | B9: Bowl de huevos | C9: Plato ligero | D9: Caliente | E9: Porción individual | F9: 1 | I9: Verificar | J9: Verificar | K9: Sí | L9: Confirmar receta y acompañamientos.
A10: DEL002 | B10: Bowl de frutas | C10: Plato ligero | D10: Fría | E10: Porción individual | F10: 1 | I10: Verificar | J10: Verificar | K10: Sí
A11: DEL003 | B11: Chipá | C11: Panificado salado | D11: Caliente/Ambiente | E11: Unidad o porción | F11: Verificar | H11: Región guaraní / Argentina | I11: Verificar | J11: Verificar | K11: Sí
A12: DEL004 | B12: Medialunas | C12: Panificado dulce | D12: Caliente/Ambiente | E12: Unidad o porción | F12: Verificar | H12: Argentina | I12: Verificar | J12: Verificar | K12: Sí
A13: DEL005 | B13: Mini budines | C13: Pastelería individual | D13: Ambiente | E13: Unidad | F13: 1 | I13: Verificar | J13: Verificar | K13: Sí | L13: Los ingredientes varían según el sabor.
A14: DEL006 | B14: Raspaditas mendocinas | C14: Panificado regional | D14: Ambiente | E14: Unidad o porción | F14: Verificar | H14: Mendoza, Argentina | I14: Verificar | J14: Verificar | K14: Sí
A15: DEL007 | B15: Smoothie bowl | C15: Plato ligero | D15: Fría | E15: Porción individual | F15: 1 | I15: Verificar | J15: Verificar | K15: Sí | L15: Confirmar ingredientes, toppings y base líquida.
A16: TEH001 | B16: Selección de té en hebras | C16: Infusión | D16: Caliente | E16: Tetera o taza | F16: 1 | I16: Verificar | J16: Verificar | K16: Sí
A17: TIS001 | B17: Tisana 1 · Cedrón & lavanda | C17: Tisana | D17: Caliente | E17: Tetera o taza | F17: 1 | I17: Verificar | J17: Verificar | K17: Sí
A18: TIS002 | B18: Tisana 2 · Limón & menta | C18: Tisana | D18: Caliente | E18: Tetera o taza | F18: 1 | I18: Verificar | J18: Verificar | K18: Sí
A19: TIS003 | B19: Tisana 3 · Manzanilla & melisa | C19: Tisana | D19: Caliente | E19: Tetera o taza | F19: 1 | I19: Verificar | J19: Verificar | K19: Sí
A20: BLE001 | B20: Del bosque | C20: Blend de té | D20: Caliente | E20: Tetera o taza | F20: 1 | I20: Verificar | J20: Verificar | K20: Sí
A21: BLE002 | B21: Detox | C21: Blend de té | D21: Caliente | E21: Tetera o taza | F21: 1 | I21: Verificar | J21: Verificar | K21: Sí
A22: BLE003 | B22: Dorado | C22: Blend de té | D22: Caliente | E22: Tetera o taza | F22: 1 | I22: Verificar | J22: Verificar | K22: Sí
A23: BLE004 | B23: Love | C23: Blend de té | D23: Caliente | E23: Tetera o taza | F23: 1 | I23: Verificar | J23: Verificar | K23: Sí
A24: ESP001 | B24: Submarino | C24: Bebida caliente | D24: Caliente | E24: Taza o vaso | F24: 1 | H24: Argentina | I24: Verificar | J24: Verificar | K24: Sí
A25: ESP002 | B25: Leche dorada | C25: Bebida caliente | D25: Caliente | E25: Taza o vaso | F25: 1 | I25: Verificar | J25: Verificar | K25: Sí
A26: CCL001 | B26: Americano | C26: Café | D26: Caliente | E26: Taza | F26: 1 | I26: Verificar | J26: Verificar | K26: Sí
A27: CCL002 | B27: Cortado | C27: Café con leche | D27: Caliente | E27: Taza | F27: 1 | I27: Verificar | J27: Verificar | K27: Sí
A28: CCL003 | B28: Café con leche | C28: Café con leche | D28: Caliente | E28: Taza | F28: 1 | I28: Verificar | J28: Verificar | K28: Sí
A29: CCL004 | B29: Lágrima | C29: Bebida con café | D29: Caliente | E29: Taza | F29: 1 | H29: Argentina | I29: Verificar | J29: Verificar | K29: Sí
A30: CCL005 | B30: Macchiato | C30: Café con leche | D30: Caliente | E30: Taza | F30: 1 | I30: Verificar | J30: Verificar | K30: Sí
A31: CCL006 | B31: Cappuccino | C31: Café con leche | D31: Caliente | E31: Taza | F31: 1 | I31: Verificar | J31: Verificar | K31: Sí
A32: CCL007 | B32: Moca | C32: Café con chocolate | D32: Caliente | E32: Taza | F32: 1 | I32: Verificar | J32: Verificar | K32: Sí
A33: CFR001 | B33: Cold brew | C33: Café frío | D33: Fría | E33: Vaso | F33: 1 | I33: Verificar | J33: Verificar | K33: Sí
A34: CFR002 | B34: Iced latte | C34: Café frío con leche | D34: Fría | E34: Vaso | F34: 1 | I34: Verificar | J34: Verificar | K34: Sí
A35: CFR003 | B35: Frappé de dulce de leche | C35: Café frío | D35: Fría | E35: Vaso | F35: 1 | I35: Verificar | J35: Verificar | K35: Sí
A36: BYJ001 | B36: Batido de banana | C36: Batido | D36: Fría | E36: Vaso | F36: 1 | I36: Verificar | J36: Verificar | K36: Sí | L36: Confirmar si la base contiene leche.
A37: BYJ002 | B37: Batido de frutos rojos | C37: Batido | D37: Fría | E37: Vaso o jarra | F37: Verificar | I37: Verificar | J37: Verificar | K37: Sí
A38: BYJ003 | B38: Limonada detox | C38: Limonada | D38: Fría | E38: Vaso o jarra | F38: Verificar | I38: Verificar | J38: Verificar | K38: Sí
A39: BYJ004 | B39: Limonada Jamaica | C39: Limonada | D39: Fría | E39: Vaso o jarra | F39: Verificar | I39: Verificar | J39: Verificar | K39: Sí
A40: BYJ005 | B40: Jugo de naranja | C40: Jugo | D40: Fría | E40: Vaso | F40: 1 | I40: Verificar | J40: Verificar | K40: Sí
A41: BYJ006 | B41: Tropical | C41: Batido | D41: Fría | E41: Vaso o jarra | F41: Verificar | I41: Verificar | J41: Verificar | K41: Sí
...

Sheet 06_Ingredientes
A1: Ingredientes declarados · Matriz preliminar
A2: La información surge del menú original y de descripciones editoriales. Debe cruzarse con recetas, fichas técnicas y etiquetas antes de utilizarse para alérgenos.
A4: ID | B4: Producto ES-AR | C4: Ingrediente 1 | D4: Ingrediente 2 | E4: Ingrediente 3 | F4: Ingrediente 4 | G4: Ingrediente 5 | H4: Ingrediente 6 | I4: Ingrediente 7 | J4: Ingrediente 8 | K4: Ingrediente 9 | L4: Ingrediente 10 | M4: Ingrediente 11 | N4: Ingrediente 12 | O4: Estado de revisión | P4: Observaciones
A5: DYM001 | B5: Avocado | C5: Huevos | D5: Palta | E5: Pan tostado | F5: Queso crema | G5: Café o té | H5: Jugo de naranja | O5: Pendiente de validación
A6: DYM002 | B6: Desayuno clásico | C6: Pan tostado | D6: Queso crema | E6: Mermelada | F6: Café o té | G6: Jugo de naranja | O6: Pendiente de validación
A7: DYM003 | B7: Desayuno mendocino | C7: Raspaditas mendocinas | D7: Café o té | E7: Jugo de naranja | O7: Pendiente de validación
A8: DYM004 | B8: Desayuno saludable | C8: Yogur | D8: Frutas de estación | E8: Granola | F8: Frutos secos | G8: Miel | H8: Coco | I8: Café o té | J8: Jugo de naranja | O8: Pendiente de validación
A9: DEL001 | B9: Bowl de huevos | C9: Huevos | D9: Acompañamientos a confirmar | O9: Pendiente de validación | P9: Confirmar receta y acompañamientos.
A10: DEL002 | B10: Bowl de frutas | C10: Frutas de estación | O10: Pendiente de validación
A11: DEL003 | B11: Chipá | C11: Almidón de mandioca | D11: Queso | E11: Huevos | F11: Leche o materia grasa a verificar | O11: Pendiente de validación
A12: DEL004 | B12: Medialunas | C12: Harina de trigo | D12: Materia grasa | E12: Azúcar | F12: Levadura | G12: Huevos o leche a verificar | O12: Pendiente de validación
A13: DEL005 | B13: Mini budines | C13: Harina | D13: Huevos | E13: Azúcar | F13: Materia grasa | G13: Sabores a confirmar | O13: Pendiente de validación | P13: Los ingredientes varían según el sabor.
A14: DEL006 | B14: Raspaditas mendocinas | C14: Harina de trigo | D14: Materia grasa | E14: Agua | F14: Sal | O14: Pendiente de validación
A15: DEL007 | B15: Smoothie bowl | C15: Frutas | D15: Toppings a confirmar | O15: Pendiente de validación | P15: Confirmar ingredientes, toppings y base líquida.
A16: TEH001 | B16: Selección de té en hebras | C16: Té negro, pu-erh o verde | D16: Agua | O16: Pendiente de validación
A17: TIS001 | B17: Tisana 1 · Cedrón & lavanda | C17: Cedrón | D17: Lavanda | E17: Manzanilla | F17: Melisa | G17: Agua | O17: Pendiente de validación
A18: TIS002 | B18: Tisana 2 · Limón & menta | C18: Limón | D18: Menta | E18: Salvia blanca | F18: Agua | O18: Pendiente de validación
A19: TIS003 | B19: Tisana 3 · Manzanilla & melisa | C19: Manzanilla | D19: Melisa | E19: Menta | F19: Agua | O19: Pendiente de validación
A20: BLE001 | B20: Del bosque | C20: Té negro | D20: Cacao | E20: Naranja | F20: Agua | O20: Pendiente de validación
A21: BLE002 | B21: Detox | C21: Té verde | D21: Jengibre | E21: Limón | F21: Menta | G21: Agua | O21: Pendiente de validación
A22: BLE003 | B22: Dorado | C22: Té verde | D22: Caléndula | E22: Durazno | F22: Limón | G22: Agua | O22: Pendiente de validación
A23: BLE004 | B23: Love | C23: Té pu-erh | D23: Hibisco | E23: Pomelo | F23: Agua | O23: Pendiente de validación
A24: ESP001 | B24: Submarino | C24: Leche | D24: Chocolate | O24: Pendiente de validación
A25: ESP002 | B25: Leche dorada | C25: Leche | D25: Anís estrellado | E25: Canela | F25: Clavo de olor | G25: Cúrcuma | H25: Jengibre | I25: Pimienta negra | O25: Pendiente de validación
A26: CCL001 | B26: Americano | C26: Café espresso | D26: Agua | O26: Pendiente de validación
A27: CCL002 | B27: Cortado | C27: Café espresso | D27: Leche | O27: Pendiente de validación
A28: CCL003 | B28: Café con leche | C28: Café | D28: Leche | O28: Pendiente de validación
A29: CCL004 | B29: Lágrima | C29: Leche | D29: Café | O29: Pendiente de validación
A30: CCL005 | B30: Macchiato | C30: Café espresso | D30: Espuma de leche | O30: Pendiente de validación
A31: CCL006 | B31: Cappuccino | C31: Café | D31: Leche | E31: Espuma de leche | O31: Pendiente de validación
A32: CCL007 | B32: Moca | C32: Café | D32: Chocolate | E32: Leche | F32: Espuma de leche | O32: Pendiente de validación
A33: CFR001 | B33: Cold brew | C33: Café | D33: Agua | O33: Pendiente de validación
A34: CFR002 | B34: Iced latte | C34: Café espresso | D34: Leche | E34: Hielo | O34: Pendiente de validación
A35: CFR003 | B35: Frappé de dulce de leche | C35: Café | D35: Leche | E35: Hielo | F35: Dulce de leche | O35: Pendiente de validación
A36: BYJ001 | B36: Batido de banana | C36: Banana | D36: Base líquida a confirmar | O36: Pendiente de validación | P36: Confirmar si la base contiene leche.
A37: BYJ002 | B37: Batido de frutos rojos | C37: Frutos rojos | D37: Jugo de naranja | O37: Pendiente de validación
A38: BYJ003 | B38: Limonada detox | C38: Agua | D38: Chía | E38: Jengibre | F38: Limón | G38: Menta | O38: Pendiente de validación
A39: BYJ004 | B39: Limonada Jamaica | C39: Agua | D39: Arándanos | E39: Hibisco | F39: Limón | O39: Pendiente de validación
A40: BYJ005 | B40: Jugo de naranja | C40: Naranja | O40: Pendiente de validación
A41: BYJ006 | B41: Tropical | C41: Mango | D41: Maracuyá | E41: Ananá | F41: Naranja | O41: Pendiente de validación
...

Sheet 07_Alérgenos_Dietas
A1: Alérgenos y preferencias alimentarias
A2: Matriz deliberadamente conservadora: «Verificar» evita publicar afirmaciones inseguras. La validación final debe realizarla Amelí con recetas y etiquetas vigentes.
A4: ID | B4: Producto ES-AR | C4: Vegetariano | D4: Vegano | E4: Sin TACC | F4: Sin lactosa | G4: Contiene gluten | H4: Contiene leche | I4: Contiene huevo | J4: Contiene soja | K4: Contiene maní | L4: Contiene frutos secos | M4: Contiene sésamo | N4: Contiene pescado | O4: Contiene mariscos | P4: Contiene alcohol | Q4: Contiene cafeína | R4: Estado de validación | S4: Advertencia / observaciones
A5: DYM001 | B5: Avocado | C5: Verificar | D5: Verificar | E5: Verificar | F5: Verificar | G5: Verificar | H5: Verificar | I5: Verificar | J5: Verificar | K5: Verificar | L5: Verificar | M5: Verificar | N5: Verificar | O5: Verificar | P5: Verificar | Q5: Verificar | R5: Pendiente
A6: DYM002 | B6: Desayuno clásico | C6: Verificar | D6: Verificar | E6: Verificar | F6: Verificar | G6: Verificar | H6: Verificar | I6: Verificar | J6: Verificar | K6: Verificar | L6: Verificar | M6: Verificar | N6: Verificar | O6: Verificar | P6: Verificar | Q6: Verificar | R6: Pendiente
A7: DYM003 | B7: Desayuno mendocino | C7: Verificar | D7: Verificar | E7: Verificar | F7: Verificar | G7: Verificar | H7: Verificar | I7: Verificar | J7: Verificar | K7: Verificar | L7: Verificar | M7: Verificar | N7: Verificar | O7: Verificar | P7: Verificar | Q7: Verificar | R7: Pendiente
A8: DYM004 | B8: Desayuno saludable | C8: Verificar | D8: Verificar | E8: Verificar | F8: Verificar | G8: Verificar | H8: Verificar | I8: Verificar | J8: Verificar | K8: Verificar | L8: Verificar | M8: Verificar | N8: Verificar | O8: Verificar | P8: Verificar | Q8: Verificar | R8: Pendiente
A9: DEL001 | B9: Bowl de huevos | C9: Verificar | D9: Verificar | E9: Verificar | F9: Verificar | G9: Verificar | H9: Verificar | I9: Verificar | J9: Verificar | K9: Verificar | L9: Verificar | M9: Verificar | N9: Verificar | O9: Verificar | P9: Verificar | Q9: Verificar | R9: Pendiente | S9: Confirmar receta y acompañamientos.
A10: DEL002 | B10: Bowl de frutas | C10: Verificar | D10: Verificar | E10: Verificar | F10: Verificar | G10: Verificar | H10: Verificar | I10: Verificar | J10: Verificar | K10: Verificar | L10: Verificar | M10: Verificar | N10: Verificar | O10: Verificar | P10: Verificar | Q10: Verificar | R10: Pendiente
A11: DEL003 | B11: Chipá | C11: Verificar | D11: Verificar | E11: Verificar | F11: Verificar | G11: Verificar | H11: Verificar | I11: Verificar | J11: Verificar | K11: Verificar | L11: Verificar | M11: Verificar | N11: Verificar | O11: Verificar | P11: Verificar | Q11: Verificar | R11: Pendiente
A12: DEL004 | B12: Medialunas | C12: Verificar | D12: Verificar | E12: Verificar | F12: Verificar | G12: Verificar | H12: Verificar | I12: Verificar | J12: Verificar | K12: Verificar | L12: Verificar | M12: Verificar | N12: Verificar | O12: Verificar | P12: Verificar | Q12: Verificar | R12: Pendiente
A13: DEL005 | B13: Mini budines | C13: Verificar | D13: Verificar | E13: Verificar | F13: Verificar | G13: Verificar | H13: Verificar | I13: Verificar | J13: Verificar | K13: Verificar | L13: Verificar | M13: Verificar | N13: Verificar | O13: Verificar | P13: Verificar | Q13: Verificar | R13: Pendiente | S13: Los ingredientes varían según el sabor.
A14: DEL006 | B14: Raspaditas mendocinas | C14: Verificar | D14: Verificar | E14: Verificar | F14: Verificar | G14: Verificar | H14: Verificar | I14: Verificar | J14: Verificar | K14: Verificar | L14: Verificar | M14: Verificar | N14: Verificar | O14: Verificar | P14: Verificar | Q14: Verificar | R14: Pendiente
A15: DEL007 | B15: Smoothie bowl | C15: Verificar | D15: Verificar | E15: Verificar | F15: Verificar | G15: Verificar | H15: Verificar | I15: Verificar | J15: Verificar | K15: Verificar | L15: Verificar | M15: Verificar | N15: Verificar | O15: Verificar | P15: Verificar | Q15: Verificar | R15: Pendiente | S15: Confirmar ingredientes, toppings y base líquida.
A16: TEH001 | B16: Selección de té en hebras | C16: Verificar | D16: Verificar | E16: Verificar | F16: Verificar | G16: Verificar | H16: Verificar | I16: Verificar | J16: Verificar | K16: Verificar | L16: Verificar | M16: Verificar | N16: Verificar | O16: Verificar | P16: Verificar | Q16: Sí | R16: Pendiente
A17: TIS001 | B17: Tisana 1 · Cedrón & lavanda | C17: Verificar | D17: Verificar | E17: Verificar | F17: Verificar | G17: Verificar | H17: Verificar | I17: Verificar | J17: Verificar | K17: Verificar | L17: Verificar | M17: Verificar | N17: Verificar | O17: Verificar | P17: Verificar | Q17: No | R17: Pendiente
A18: TIS002 | B18: Tisana 2 · Limón & menta | C18: Verificar | D18: Verificar | E18: Verificar | F18: Verificar | G18: Verificar | H18: Verificar | I18: Verificar | J18: Verificar | K18: Verificar | L18: Verificar | M18: Verificar | N18: Verificar | O18: Verificar | P18: Verificar | Q18: No | R18: Pendiente
A19: TIS003 | B19: Tisana 3 · Manzanilla & melisa | C19: Verificar | D19: Verificar | E19: Verificar | F19: Verificar | G19: Verificar | H19: Verificar | I19: Verificar | J19: Verificar | K19: Verificar | L19: Verificar | M19: Verificar | N19: Verificar | O19: Verificar | P19: Verificar | Q19: No | R19: Pendiente
A20: BLE001 | B20: Del bosque | C20: Verificar | D20: Verificar | E20: Verificar | F20: Verificar | G20: Verificar | H20: Verificar | I20: Verificar | J20: Verificar | K20: Verificar | L20: Verificar | M20: Verificar | N20: Verificar | O20: Verificar | P20: Verificar | Q20: Sí | R20: Pendiente
A21: BLE002 | B21: Detox | C21: Verificar | D21: Verificar | E21: Verificar | F21: Verificar | G21: Verificar | H21: Verificar | I21: Verificar | J21: Verificar | K21: Verificar | L21: Verificar | M21: Verificar | N21: Verificar | O21: Verificar | P21: Verificar | Q21: Sí | R21: Pendiente
A22: BLE003 | B22: Dorado | C22: Verificar | D22: Verificar | E22: Verificar | F22: Verificar | G22: Verificar | H22: Verificar | I22: Verificar | J22: Verificar | K22: Verificar | L22: Verificar | M22: Verificar | N22: Verificar | O22: Verificar | P22: Verificar | Q22: Sí | R22: Pendiente
A23: BLE004 | B23: Love | C23: Verificar | D23: Verificar | E23: Verificar | F23: Verificar | G23: Verificar | H23: Verificar | I23: Verificar | J23: Verificar | K23: Verificar | L23: Verificar | M23: Verificar | N23: Verificar | O23: Verificar | P23: Verificar | Q23: Sí | R23: Pendiente
A24: ESP001 | B24: Submarino | C24: Verificar | D24: Verificar | E24: Verificar | F24: Verificar | G24: Verificar | H24: Verificar | I24: Verificar | J24: Verificar | K24: Verificar | L24: Verificar | M24: Verificar | N24: Verificar | O24: Verificar | P24: Verificar | Q24: Verificar | R24: Pendiente
A25: ESP002 | B25: Leche dorada | C25: Verificar | D25: Verificar | E25: Verificar | F25: Verificar | G25: Verificar | H25: Verificar | I25: Verificar | J25: Verificar | K25: Verificar | L25: Verificar | M25: Verificar | N25: Verificar | O25: Verificar | P25: Verificar | Q25: Verificar | R25: Pendiente
A26: CCL001 | B26: Americano | C26: Verificar | D26: Verificar | E26: Verificar | F26: Verificar | G26: Verificar | H26: Verificar | I26: Verificar | J26: Verificar | K26: Verificar | L26: Verificar | M26: Verificar | N26: Verificar | O26: Verificar | P26: Verificar | Q26: Sí | R26: Pendiente
A27: CCL002 | B27: Cortado | C27: Verificar | D27: Verificar | E27: Verificar | F27: Verificar | G27: Verificar | H27: Verificar | I27: Verificar | J27: Verificar | K27: Verificar | L27: Verificar | M27: Verificar | N27: Verificar | O27: Verificar | P27: Verificar | Q27: Sí | R27: Pendiente
... A35: CFR003 | B35: Frappé de dulce de leche | C35: Verificar | D35: Verificar | E35: Verificar | F35: Verificar | G35: Verificar | H35: Verificar | I35: Verificar | J35: Verificar | K35: Verificar | L35: Verificar | M35: Verificar | N35: Verificar | O35: Verificar | P35: Verificar | Q35: Sí | R35: Pendiente
A36: BYJ001 | B36: Batido de banana | C36: Verificar | D36: Verificar | E36: Verificar | F36: Verificar | G36: Verificar | H36: Verificar | I36: Verificar | J36: Verificar | K36: Verificar | L36: Verificar | M36: Verificar | N36: Verificar | O36: Verificar | P36: Verificar | Q36: Verificar | R36: Pendiente | S36: Confirmar si la base contiene leche.
A37: BYJ002 | B37: Batido de frutos rojos | C37: Verificar | D37: Verificar | E37: Verificar | F37: Verificar | G37: Verificar | H37: Verificar | I37: Verificar | J37: Verificar | K37: Verificar | L37: Verificar | M37: Verificar | N37: Verificar | O37: Verificar | P37: Verificar | Q37: Verificar | R37: Pendiente
A38: BYJ003 | B38: Limonada detox | C38: Verificar | D38: Verificar | E38: Verificar | F38: Verificar | G38: Verificar | H38: Verificar | I38: Verificar | J38: Verificar | K38: Verificar | L38: Verificar | M38: Verificar | N38: Verificar | O38: Verificar | P38: Verificar | Q38: Verificar | R38: Pendiente
A39: BYJ004 | B39: Limonada Jamaica | C39: Verificar | D39: Verificar | E39: Verificar | F39: Verificar | G39: Verificar | H39: Verificar | I39: Verificar | J39: Verificar | K39: Verificar | L39: Verificar | M39: Verificar | N39: Verificar | O39: Verificar | P39: Verificar | Q39: Verificar | R39: Pendiente
A40: BYJ005 | B40: Jugo de naranja | C40: Verificar | D40: Verificar | E40: Verificar | F40: Verificar | G40: Verificar | H40: Verificar | I40: Verificar | J40: Verificar | K40: Verificar | L40: Verificar | M40: Verificar | N40: Verificar | O40: Verificar | P40: Verificar | Q40: Verificar | R40: Pendiente
A41: BYJ006 | B41: Tropical | C41: Verificar | D41: Verificar | E41: Verificar | F41: Verificar | G41: Verificar | H41: Verificar | I41: Verificar | J41: Verificar | K41: Verificar | L41: Verificar | M41: Verificar | N41: Verificar | O41: Verificar | P41: Verificar | Q41: Verificar | R41: Pendiente
A42: ADI001 | B42: Leche vegetal | C42: Verificar | D42: Verificar | E42: Verificar | F42: Verificar | G42: Verificar | H42: Verificar | I42: Verificar | J42: Verificar | K42: Verificar | L42: Verificar | M42: Verificar | N42: Verificar | O42: Verificar | P42: Verificar | Q42: Verificar | R42: Pendiente
A43: ADI002 | B43: Leche sin lactosa | C43: Verificar | D43: Verificar | E43: Verificar | F43: Verificar | G43: Verificar | H43: Verificar | I43: Verificar | J43: Verificar | K43: Verificar | L43: Verificar | M43: Verificar | N43: Verificar | O43: Verificar | P43: Verificar | Q43: Verificar | R43: Pendiente
A44: STC001 | B44: Postres sin TACC | C44: Verificar | D44: Verificar | E44: Sí | F44: Verificar | G44: Verificar | H44: Verificar | I44: Verificar | J44: Verificar | K44: Verificar | L44: Verificar | M44: Verificar | N44: Verificar | O44: Verificar | P44: Verificar | Q44: Verificar | R44: Pendiente | S44: Producto tercerizado: validar certificación vigente, proveedor, almacenamiento, utensilios y riesgo de contaminación cruzada.
A45: STC002 | B45: Pasta frola sin TACC | C45: Verificar | D45: Verificar | E45: Sí | F45: Verificar | G45: Verificar | H45: Verificar | I45: Verificar | J45: Verificar | K45: Verificar | L45: Verificar | M45: Verificar | N45: Verificar | O45: Verificar | P45: Verificar | Q45: Verificar | R45: Pendiente | S45: Producto tercerizado: validar certificación vigente, proveedor, almacenamiento, utensilios y riesgo de contaminación cruzada.
A46: STC003 | B46: Tarta de coco y dulce de leche sin TACC | C46: Verificar | D46: Verificar | E46: Sí | F46: Verificar | G46: Verificar | H46: Verificar | I46: Verificar | J46: Verificar | K46: Verificar | L46: Verificar | M46: Verificar | N46: Verificar | O46: Verificar | P46: Verificar | Q46: Verificar | R46: Pendiente | S46: Producto tercerizado: validar certificación vigente, proveedor, almacenamiento, utensilios y riesgo de contaminación cruzada.
A47: STC004 | B47: Alfacookie sin TACC | C47: Verificar | D47: Verificar | E47: Sí | F47: Verificar | G47: Verificar | H47: Verificar | I47: Verificar | J47: Verificar | K47: Verificar | L47: Verificar | M47: Verificar | N47: Verificar | O47: Verificar | P47: Verificar | Q47: Verificar | R47: Pendiente | S47: Producto tercerizado: validar certificación vigente, proveedor, almacenamiento, utensilios y riesgo de contaminación cruzada.
A48: TYT001 | B48: Torta Amelí | C48: Verificar | D48: Verificar | E48: Verificar | F48: Verificar | G48: Verificar | H48: Verificar | I48: Verificar | J48: Verificar | K48: Verificar | L48: Verificar | M48: Verificar | N48: Verificar | O48: Verificar | P48: Verificar | Q48: Verificar | R48: Pendiente
...

Sheet 08_Personalización
A1: Personalización y adicionales
A2: Usar «Verificar» hasta definir reglas de cocina, recargos y disponibilidad. Las opciones visibles en el menú deben coincidir con la operación real.
A4: ID | B4: Producto ES-AR | C4: Admite cambios | D4: Leche vegetal | E4: Leche sin lactosa | F4: Extra espresso | G4: Extra crema | H4: Extra queso | I4: Extra palta | J4: Extra miel | K4: Extra dulce de leche | L4: Sin azúcar añadida | M4: Opción para llevar | N4: Observaciones
A5: DYM001 | B5: Avocado | C5: Verificar | D5: No | E5: No | F5: No | G5: Verificar | H5: Verificar | I5: Verificar | J5: Verificar | K5: Verificar | L5: No | M5: Verificar
A6: DYM002 | B6: Desayuno clásico | C6: Verificar | D6: No | E6: No | F6: No | G6: Verificar | H6: Verificar | I6: Verificar | J6: Verificar | K6: Verificar | L6: No | M6: Verificar
A7: DYM003 | B7: Desayuno mendocino | C7: Verificar | D7: No | E7: No | F7: No | G7: Verificar | H7: Verificar | I7: Verificar | J7: Verificar | K7: Verificar | L7: No | M7: Verificar
A8: DYM004 | B8: Desayuno saludable | C8: Verificar | D8: No | E8: No | F8: No | G8: Verificar | H8: Verificar | I8: Verificar | J8: Verificar | K8: Verificar | L8: No | M8: Verificar
A9: DEL001 | B9: Bowl de huevos | C9: Verificar | D9: No | E9: No | F9: No | G9: Verificar | H9: Verificar | I9: Verificar | J9: Verificar | K9: Verificar | L9: No | M9: Sí | N9: Confirmar receta y acompañamientos.
A10: DEL002 | B10: Bowl de frutas | C10: Verificar | D10: No | E10: No | F10: No | G10: Verificar | H10: Verificar | I10: Verificar | J10: Verificar | K10: Verificar | L10: No | M10: Sí
A11: DEL003 | B11: Chipá | C11: Verificar | D11: No | E11: No | F11: No | G11: Verificar | H11: Verificar | I11: Verificar | J11: Verificar | K11: Verificar | L11: No | M11: Sí
A12: DEL004 | B12: Medialunas | C12: Verificar | D12: No | E12: No | F12: No | G12: Verificar | H12: Verificar | I12: Verificar | J12: Verificar | K12: Verificar | L12: No | M12: Sí
A13: DEL005 | B13: Mini budines | C13: Verificar | D13: No | E13: No | F13: No | G13: Verificar | H13: Verificar | I13: Verificar | J13: Verificar | K13: Verificar | L13: No | M13: Sí | N13: Los ingredientes varían según el sabor.
A14: DEL006 | B14: Raspaditas mendocinas | C14: Verificar | D14: No | E14: No | F14: No | G14: Verificar | H14: Verificar | I14: Verificar | J14: Verificar | K14: Verificar | L14: No | M14: Sí
A15: DEL007 | B15: Smoothie bowl | C15: Verificar | D15: No | E15: No | F15: No | G15: Verificar | H15: Verificar | I15: Verificar | J15: Verificar | K15: Verificar | L15: No | M15: Sí | N15: Confirmar ingredientes, toppings y base líquida.
A16: TEH001 | B16: Selección de té en hebras | C16: Sí | D16: No | E16: No | F16: No | G16: Verificar | H16: Verificar | I16: Verificar | J16: Verificar | K16: Verificar | L16: Verificar | M16: Sí
A17: TIS001 | B17: Tisana 1 · Cedrón & lavanda | C17: Sí | D17: No | E17: No | F17: No | G17: Verificar | H17: Verificar | I17: Verificar | J17: Verificar | K17: Verificar | L17: Verificar | M17: Sí
A18: TIS002 | B18: Tisana 2 · Limón & menta | C18: Sí | D18: No | E18: No | F18: No | G18: Verificar | H18: Verificar | I18: Verificar | J18: Verificar | K18: Verificar | L18: Verificar | M18: Sí
A19: TIS003 | B19: Tisana 3 · Manzanilla & melisa | C19: Sí | D19: No | E19: No | F19: No | G19: Verificar | H19: Verificar | I19: Verificar | J19: Verificar | K19: Verificar | L19: Verificar | M19: Sí
A20: BLE001 | B20: Del bosque | C20: Sí | D20: No | E20: No | F20: No | G20: Verificar | H20: Verificar | I20: Verificar | J20: Verificar | K20: Verificar | L20: Verificar | M20: Sí
A21: BLE002 | B21: Detox | C21: Sí | D21: No | E21: No | F21: No | G21: Verificar | H21: Verificar | I21: Verificar | J21: Verificar | K21: Verificar | L21: Verificar | M21: Sí
A22: BLE003 | B22: Dorado | C22: Sí | D22: No | E22: No | F22: No | G22: Verificar | H22: Verificar | I22: Verificar | J22: Verificar | K22: Verificar | L22: Verificar | M22: Sí
A23: BLE004 | B23: Love | C23: Sí | D23: No | E23: No | F23: No | G23: Verificar | H23: Verificar | I23: Verificar | J23: Verificar | K23: Verificar | L23: Verificar | M23: Sí
A24: ESP001 | B24: Submarino | C24: Sí | D24: Sí | E24: Sí | F24: No | G24: Verificar | H24: Verificar | I24: Verificar | J24: Verificar | K24: Verificar | L24: Verificar | M24: Sí
A25: ESP002 | B25: Leche dorada | C25: Sí | D25: Sí | E25: Sí | F25: No | G25: Verificar | H25: Verificar | I25: Verificar | J25: Verificar | K25: Verificar | L25: Verificar | M25: Sí
A26: CCL001 | B26: Americano | C26: Sí | D26: No | E26: No | F26: Sí | G26: Verificar | H26: Verificar | I26: Verificar | J26: Verificar | K26: Verificar | L26: Verificar | M26: Sí
